<?xml version="1.0"?>
<robot name="x50">

	<material name="white">
		<color rgba="0.5 0.5 0.5 1"/>
	</material>

	<link name="root">
		<visual>
			<geometry>
				<mesh filename="package://x50_description/meshes/RBase.stl" scale="0.001 0.001 0.001"/>
			</geometry>
			<origin rpy="0 0 0" xyz="0 0 0"/>
			<material name="white" />
		</visual>
		<collision>
			<geometry>
				<mesh filename="package://x50_description/meshes/RBase.stl" scale="0.001 0.001 0.001"/>
			</geometry>
			<origin rpy="0 0 0" xyz="0 0 0"/>
		</collision>
	</link>

	<link name="link1">
		<visual>
			<geometry>
				<mesh filename="package://x50_description/meshes/RLink1.stl" scale="0.001 0.001 0.001"/>
			</geometry>
			<origin rpy="0 0 0" xyz="0 0 0"/>
			<material name="white" />
		</visual>
		<collision>
			<geometry>
				<mesh filename="package://x50_description/meshes/RLink1.stl" scale="0.001 0.001 0.001"/>
			</geometry>
			<origin rpy="0 0 0" xyz="0 0 0"/>
		</collision>
	</link>

	<link name="link2">
		<visual>
			<geometry>
				<mesh filename="package://x50_description/meshes/RLink2.stl" scale="0.001 0.001 0.001"/>
			</geometry>
			<origin rpy="0 0 0" xyz="0 0 0"/>
			<material name="white" />
		</visual>
		<collision>
			<geometry>
				<mesh filename="package://x50_description/meshes/RLink2.stl" scale="0.001 0.001 0.001"/>
			</geometry>
			<origin rpy="0 0 0" xyz="0 0 0"/>
		</collision>
	</link>

	<link name="link3">
		<visual>
			<geometry>
				<mesh filename="package://x50_description/meshes/RLink3.stl" scale="0.001 0.001 0.001"/>
			</geometry>
			<origin rpy="0 0 0" xyz="0 0 0"/>
			<material name="white" />
		</visual>
		<collision>
			<geometry>
				<mesh filename="package://x50_description/meshes/RLink3.stl" scale="0.001 0.001 0.001"/>
			</geometry>
			<origin rpy="0 0 0" xyz="0 0 0"/>
		</collision>
	</link>

	<link name="link4">
		<visual>
			<geometry>
				<mesh filename="package://x50_description/meshes/RLink4.stl" scale="0.001 0.001 0.001"/>
			</geometry>
			<origin rpy="0 0 0" xyz="0 0 0"/>
			<material name="white" />
		</visual>
		<collision>
			<geometry>
				<mesh filename="package://x50_description/meshes/RLink4.stl" scale="0.001 0.001 0.001"/>
			</geometry>
			<origin rpy="0 0 0" xyz="0 0 0"/>
		</collision>
	</link>

	<link name="link5">
		<visual>
			<geometry>
				<mesh filename="package://x50_description/meshes/RLink5.stl" scale="0.001 0.001 0.001"/>
			</geometry>
			<origin rpy="0 0 0" xyz="0 0 0"/>
			<material name="white" />
		</visual>
		<collision>
			<geometry>
				<mesh filename="package://x50_description/meshes/RLink5.stl" scale="0.001 0.001 0.001"/>
			</geometry>
			<origin rpy="0 0 0" xyz="0 0 0"/>
		</collision>
	</link>

	<link name="link6">
	</link>

	<link name="tool">
		<visual>
			<geometry>
				<box size="0.1 0.1 0.1"/>
			</geometry>
			<origin rpy="0 0 0" xyz="0 0 0"/>
			<material name="white" />
		</visual>
		<collision>
			<geometry>
				<box size="0.1 0.1 0.1"/>
			</geometry>
			<origin rpy="0 0 0" xyz="0 0 0"/>
		</collision>
	</link>

	<joint name="joint_1" type="revolute">
		<parent link="root"/>
		<child link="link1"/>
		<origin xyz="0 0 0.23" rpy="0 0 0" />
		<axis xyz="0 0 1" />
		<limit effort="2548.0" velocity="0.261799383" lower="-1.5707963" upper="1.5707963" />
	</joint>

	<joint name="joint_2" type="revolute">
		<parent link="link1"/>
		<child link="link2"/>
		<origin xyz="0 0.200 0.449" rpy="0 0 0" />
		<axis xyz="1 0 0" />
		<limit effort="3136.0" velocity="0.261799383" lower="-1.047197533" upper="1.047197533" />
	</joint>

	<joint name="joint_3" type="revolute">
		<parent link="link2"/>
		<child link="link3"/>
		<origin xyz="0 0 0.890" rpy="0 0 0" />
		<axis xyz="1 0 0" />
		<limit effort="1225.0" velocity="0.261799383" lower="-1.047197533" upper="1.047197533" />
	</joint>

	<joint name="joint_4" type="revolute">
		<parent link="link3"/>
		<child link="link4"/>
		<origin xyz="0 0.4369 0.195" rpy="0 0 0" />
		<axis xyz="0 -1 0" />
		<limit effort="588.0" velocity="2.617993833" lower="-6.2832" upper="6.2832" />
	</joint>

	<joint name="joint_5" type="revolute">
		<parent link="link4"/>
		<child link="link5"/>
		<origin xyz="0 0.1995 0" rpy="0 0 0" />
		<axis xyz="1 0 0" />
		<limit effort="412.0" velocity="0.261799383" lower="-1.5707963" upper="1.5707963" />
	</joint>

	<joint name="joint_6" type="revolute">
		<parent link="link5"/>
		<child link="link6"/>
		<origin xyz="0 0.238 0" rpy="0 0 0" />
		<axis xyz="0 -1 0" />
		<limit effort="343.0" velocity="2.617993833" lower="-6.2832" upper="6.2832" />
	</joint>

	<joint name="jointT" type="fixed">
		<parent link="link6"/>
		<child link="tool"/>
		<origin xyz="0 0.1 0" rpy="0 0 0" />
	</joint>

</robot>
