<?xml version="1.0"?>
<robot
  name="scara">
  <link
    name="root">
    <visual>
      <origin
        xyz="0 0 0"
        rpy="0 0 0" />
      <geometry>
        <mesh
          filename="package://description/meshes/base_link.STL" />
      </geometry>
      <material
        name="">
        <color
          rgba="1 1 1 1" />
      </material>
    </visual>
    <collision>
      <origin
        xyz="0 0 0"
        rpy="0 0 0" />
      <geometry>
        <mesh
          filename="package://description/meshes/base_link.STL" />
      </geometry>
    </collision>
  </link>
  <link
    name="Link_1">
    <inertial>
      <origin
        xyz="0.19562 -7.6778E-09 -0.026915"
        rpy="0 0 0" />
      <mass
        value="3.9067" />
      <inertia
        ixx="0.0071958"
        ixy="-2.1719E-11"
        ixz="0.00031641"
        iyy="0.090992"
        iyz="-2.4416E-12"
        izz="0.096353" />
    </inertial>
    <visual>
      <origin
        xyz="0 0 0"
        rpy="0 0 0" />
      <geometry>
        <mesh
          filename="package://description/meshes/Link_1.STL" />
      </geometry>
      <material
        name="">
        <color
          rgba="1 1 1 1" />
      </material>
    </visual>
    <collision>
      <origin
        xyz="0 0 0"
        rpy="0 0 0" />
      <geometry>
        <mesh
          filename="package://description/meshes/Link_1.STL" />
      </geometry>
    </collision>
  </link>
  <joint
    name="Joint_1"
    type="revolute">
    <origin
      xyz="0 0 0.254"
      rpy="0 0 0" />
    <parent
      link="root" />
    <child
      link="Link_1" />
    <axis
      xyz="0 0 1" />
    <limit
      lower="-1.0472"
      upper="1.0472"
      effort="2548.0"
      velocity="0.261799383" />
  </joint>
  <link
    name="Link_2">
    <inertial>
      <origin
        xyz="0.10989 -4.2606E-05 0.067917"
        rpy="0 0 0" />
      <mass
        value="4.2305" />
      <inertia
        ixx="0.027444"
        ixy="-4.6311E-06"
        ixz="-0.0052217"
        iyy="0.064522"
        iyz="2.508E-05"
        izz="0.048287" />
    </inertial>
    <visual>
      <origin
        xyz="0 0 0"
        rpy="0 0 0" />
      <geometry>
        <mesh
          filename="package://description/meshes/Link_2.STL" />
      </geometry>
      <material
        name="">
        <color
          rgba="1 1 1 1" />
      </material>
    </visual>
    <collision>
      <origin
        xyz="0 0 0"
        rpy="0 0 0" />
      <geometry>
        <mesh
          filename="package://description/meshes/Link_2.STL" />
      </geometry>
    </collision>
  </link>
  <joint
    name="Joint_2"
    type="revolute">
    <origin
      xyz="0.4 0 0"
      rpy="0 0 0" />
    <parent
      link="Link_1" />
    <child
      link="Link_2" />
    <axis
      xyz="0 0 1" />
    <limit
      lower="-1.0472"
      upper="1.0472"
      effort="2548.0"
      velocity="0.261799383" />
  </joint>
  <link
    name="Link_3">
    <inertial>
      <origin
        xyz="3.4238E-06 0.0004897 -0.18826"
        rpy="0 0 0" />
      <mass
        value="0.10681" />
      <inertia
        ixx="0.00233"
        ixy="-2.6775E-11"
        ixz="5.5304E-08"
        iyy="0.0023302"
        iyz="-4.6131E-06"
        izz="1.1087E-05" />
    </inertial>
    <visual>
      <origin
        xyz="0 0 0"
        rpy="3.1415926 0 0" />
      <geometry>
        <mesh
          filename="package://description/meshes/Link_3.STL" />
      </geometry>
      <material
        name="">
        <color
          rgba="1 1 1 1" />
      </material>
    </visual>
    <collision>
      <origin
        xyz="0 0 0"
        rpy="0 0 0" />
      <geometry>
        <mesh
          filename="package://description/meshes/Link_3.STL" />
      </geometry>
    </collision>
  </link>
  <joint
    name="Joint_3"
    type="prismatic">
    <origin
      xyz="0.25 0 -0.16"
      rpy="0 0 0" />
    <parent
      link="Link_2" />
    <child
      link="Link_3" />
    <axis
      xyz="0 0 -1" />
    <limit
      lower="0"
      upper="0.16"
      effort="2548.0"
      velocity="0.1" />
  </joint>
  <link
    name="Link_4">
    <inertial>
      <origin
        xyz="3.4238E-06 0.0004897 -0.18826"
        rpy="0 0 0" />
      <mass
        value="0.10681" />
      <inertia
        ixx="0.00233"
        ixy="-2.6775E-11"
        ixz="5.5304E-08"
        iyy="0.0023302"
        iyz="-4.6131E-06"
        izz="1.1087E-05" />
    </inertial>
    <visual>
      <origin
        xyz="0 0 0"
        rpy="3.1415926 0 0" />
      <geometry>
        <mesh
          filename="package://description/meshes/Link_4.STL" />
      </geometry>
      <material
        name="">
        <color
          rgba="1 1 1 1" />
      </material>
    </visual>
    <collision>
      <origin
        xyz="0 0 0"
        rpy="0 0 0" />
      <geometry>
        <mesh
          filename="package://description/meshes/Link_4.STL" />
      </geometry>
    </collision>
  </link>
  <joint
    name="Joint_4"
    type="revolute">
    <origin
      xyz="0 0 0"
      rpy="0 0 0" />
    <parent
      link="Link_3" />
    <child
      link="Link_4" />
    <axis
      xyz="0 0 -1" />
    <limit
      lower="-1.0472"
      upper="1.0472"
      effort="2548.0"
      velocity="0.261799383" />
  </joint>
  <link name="tool">
	<visual>
		<geometry>
			<box size="0.1 0.1 0.1"/>
		</geometry>
		<origin rpy="0 0 0" xyz="0 0 0"/>
		<material name="white" />
	</visual>
	<collision>
		<geometry>
			<box size="0.1 0.1 0.1"/>
		</geometry>
		<origin rpy="0 0 0" xyz="0 0 0"/>
	</collision>
  </link>
  <joint name="jointT" type="fixed">
	<parent link="Link_4"/>
	<child link="tool"/>
	<origin xyz="0 0 0" rpy="0 0 0" />
  </joint>
</robot>
